Workbook

Sheet DCF
B1: Vertiv Holdings (VRT) — DCF 估值模型
B2: Ticker: VRT | 日期: 2026-06-18 | 會計年底: 12月 | 單位: US$ bn（每股除外）| 期中折現慣例
B4: 情境選擇 (1熊 2基 3牛) | C4: 2
B5: 目前情境 | C5: =IF($C$4=1,"熊 Bear",IF($C$4=2,"基 Base","牛 Bull"))
B7: 市場資料 MARKET DATA（與情境無關）
B8: 現價 Stock Price ($) | C8: 320
B9: 稀釋股數 Diluted Shares (bn) | C9: 0.382
B10: 市值 Market Cap | C10: =C8*C9
B11: 淨負債 Net Debt (連結 WACC) | C11: =WACC!$C$20
B13: 情境假設 SCENARIO ASSUMPTIONS（營收成長 / EBIT 利潤率）
B14: 熊 BEAR CASE
B15: 假設項目 | D15: FY26E | E15: FY27E | F15: FY28E | G15: FY29E | H15: FY30E
B16: 營收成長 % | D16: 0.22 | E16: 0.14 | F16: 0.09 | G16: 0.06 | H16: 0.04
B17: EBIT 利潤率 % | D17: 0.185 | E17: 0.19 | F17: 0.195 | G17: 0.2 | H17: 0.2
B18: 基 BASE CASE
B19: 假設項目 | D19: FY26E | E19: FY27E | F19: FY28E | G19: FY29E | H19: FY30E
B20: 營收成長 % | D20: 0.27 | E20: 0.2 | F20: 0.15 | G20: 0.11 | H20: 0.08
B21: EBIT 利潤率 % | D21: 0.195 | E21: 0.205 | F21: 0.215 | G21: 0.22 | H21: 0.225
B22: 牛 BULL CASE
B23: 假設項目 | D23: FY26E | E23: FY27E | F23: FY28E | G23: FY29E | H23: FY30E
B24: 營收成長 % | D24: 0.32 | E24: 0.26 | F24: 0.2 | G24: 0.15 | H24: 0.11
B25: EBIT 利潤率 % | D25: 0.2 | E25: 0.215 | F25: 0.23 | G25: 0.24 | H25: 0.245
B26: 選定情境 SELECTED（=CHOOSE 由選擇器）
B27: 選定營收成長 % | D27: =CHOOSE($C$4,D16,D20,D24) | E27: =CHOOSE($C$4,E16,E20,E24) | F27: =CHOOSE($C$4,F16,F20,F24) | G27: =CHOOSE($C$4,G16,G20,G24) | H27: =CHOOSE($C$4,H16,H20,H24)
B28: 選定 EBIT 利潤率 % | D28: =CHOOSE($C$4,D17,D21,D25) | E28: =CHOOSE($C$4,E17,E21,E25) | F28: =CHOOSE($C$4,F17,F21,F25) | G28: =CHOOSE($C$4,G17,G21,G25) | H28: =CHOOSE($C$4,H17,H21,H25)
B30: 全域假設 GLOBAL ASSUMPTIONS（與情境無關）
B31: 稅率 Tax Rate | C31: 0.21
B32: 稅率 (供 WACC 連結) | C32: =C31
B33: D&A % 營收 | C33: 0.026
B34: Capex % 營收 | C34: 0.023
B35: ΔNWC % 增額營收 | C35: 0.08
B36: 終值成長 g | C36: 0.03
B37: WACC (連結 WACC 分頁) | C37: =WACC!$C$27
B39: 財務預測 PROJECTIONS (US$ bn)
B40: 項目 \ 年度 | C40: FY25A | D40: FY26E | E40: FY27E | F40: FY28E | G40: FY29E | H40: FY30E
B41: 營收 Revenue | C41: 10.84 | D41: =C41*(1+D27) | E41: =D41*(1+E27) | F41: =E41*(1+F27) | G41: =F41*(1+G27) | H41: =G41*(1+H27)
B42: 營收成長 % | D42: =D41/C41-1 | E42: =E41/D41-1 | F42: =F41/E41-1 | G42: =G41/F41-1 | H42: =H41/G41-1
B43: EBIT 利潤率 % | C43: 0.188 | D43: =D28 | E43: =E28 | F43: =F28 | G43: =G28 | H43: =H28
B44: EBIT | C44: =C41*C43 | D44: =D41*D43 | E44: =E41*E43 | F44: =F41*F43 | G44: =G41*G43 | H44: =H41*H43
B45: 減：稅 Taxes | C45: =C44*$C$31 | D45: =D44*$C$31 | E45: =E44*$C$31 | F45: =F44*$C$31 | G45: =G44*$C$31 | H45: =H44*$C$31
...

Sheet WACC
B1: Vertiv (VRT) — WACC（資金成本，CAPM）
B3: 權益成本 COST OF EQUITY
B4: 無風險利率 (10Y UST) | C4: 0.043
B5: Beta (5年月beta) | C5: 1.45
B6: 股權風險溢酬 ERP | C6: 0.05
B7: 權益成本 Cost of Equity | C7: =C4+C5*C6
B9: 負債成本 COST OF DEBT
B10: 稅前負債成本 | C10: 0.055
B11: 稅率 (連結 DCF) | C11: =DCF!$C$32
B12: 稅後負債成本 | C12: =C10*(1-C11)
B14: 資本結構 CAPITAL STRUCTURE ($bn)
B15: 股價 (連結 DCF) | C15: =DCF!$C$8
B16: 股數 bn (連結 DCF) | C16: =DCF!$C$9
B17: 市值 Market Cap | C17: =C15*C16
B18: 總負債 Total Debt | C18: 2.9
B19: 現金 Cash & Equiv | C19: 1
B20: 淨負債 Net Debt | C20: =C18-C19
B21: 企業價值 EV | C21: =C17+C20
B23: WACC 計算 | C23: 權重 | D23: 成本 | E23: 貢獻
B24: 權益 Equity | C24: =C17/C21 | D24: =C7 | E24: =C24*D24
B25: 負債 Debt | C25: =C20/C21 | D25: =C12 | E25: =C25*D25
B27: WACC | C27: =E24+E25
