Workbook

Sheet DCF
B1: Vertiv Holdings (VRT) — DCF 估值模型 | K1: 輸入 INPUTS
B2: 單位：US$ bn（除每股/倍數）· 活公式，開啟即重算 · 資料時點 2026/6 · 僅供研究參考 | K2: 情境 (1熊 2基 3牛) | L2: 2
K3: WACC | L3: 0.1
K4: 終值成長 g | L4: 0.035
K5: 終值 EV/EBITDA | L5: 22
K6: 稅率 | L6: 0.21
B7: 項目 \ 年度 | D7: FY25A | E7: FY26E | F7: FY27E | G7: FY28E | H7: FY29E | I7: FY30E | K7: D&A %營收 | L7: 0.026
B8: 營收 Revenue | D8: 10.84 | E8: =D8*(1+E9) | F8: =E8*(1+F9) | G8: =F8*(1+G9) | H8: =G8*(1+H9) | I8: =H8*(1+I9) | K8: Capex %營收 | L8: 0.023
B9: 營收成長 % | D9: 0.28 | E9: =CHOOSE($L$2,E28,E29,E30) | F9: =CHOOSE($L$2,F28,F29,F30) | G9: =CHOOSE($L$2,G28,G29,G30) | H9: =CHOOSE($L$2,H28,H29,H30) | I9: =CHOOSE($L$2,I28,I29,I30) | K9: ΔNWC %增額營收 | L9: 0.08
B10: EBIT 利潤率 % | D10: 0.19 | E10: =CHOOSE($L$2,E32,E33,E34) | F10: =CHOOSE($L$2,F32,F33,F34) | G10: =CHOOSE($L$2,G32,G33,G34) | H10: =CHOOSE($L$2,H32,H33,H34) | I10: =CHOOSE($L$2,I32,I33,I34) | K10: 淨負債 $bn | L10: 2
B11: EBIT (營業利益) | D11: =D8*D10 | E11: =E8*E10 | F11: =F8*F10 | G11: =G8*G10 | H11: =H8*H10 | I11: =I8*I10 | K11: 股數 (bn) | L11: 0.382
B12: 減：稅 (NOPAT 稅) | E12: =E11*$L$6 | F12: =F11*$L$6 | G12: =G11*$L$6 | H12: =H11*$L$6 | I12: =I11*$L$6 | K12: 現價 $ | L12: 320
B13: NOPAT | E13: =E11-E12 | F13: =F11-F12 | G13: =G11-G12 | H13: =H11-H12 | I13: =I11-I12
B14: 加：折舊攤銷 D&A | D14: =D8*$L$7 | E14: =E8*$L$7 | F14: =F8*$L$7 | G14: =G8*$L$7 | H14: =H8*$L$7 | I14: =I8*$L$7
B15: 減：資本支出 Capex | E15: =E8*$L$8 | F15: =F8*$L$8 | G15: =G8*$L$8 | H15: =H8*$L$8 | I15: =I8*$L$8
B16: 減：營運資金增加 ΔNWC | E16: =(E8-D8)*$L$9 | F16: =(F8-E8)*$L$9 | G16: =(G8-F8)*$L$9 | H16: =(H8-G8)*$L$9 | I16: =(I8-H8)*$L$9
B17: 無槓桿自由現金流 FCFF | E17: =E13+E14-E15-E16 | F17: =F13+F14-F15-F16 | G17: =G13+G14-G15-G16 | H17: =H13+H14-H15-H16 | I17: =I13+I14-I15-I16
B18: 期數 t | E18: 1 | F18: 2 | G18: 3 | H18: 4 | I18: 5
B19: 折現因子 | E19: =1/(1+$L$3)^E18 | F19: =1/(1+$L$3)^F18 | G19: =1/(1+$L$3)^G18 | H19: =1/(1+$L$3)^H18 | I19: =1/(1+$L$3)^I18
B20: FCFF 現值 PV | E20: =E17*E19 | F20: =F17*F19 | G20: =G17*G19 | H20: =H17*H19 | I20: =I17*I19
B22: 備忘：EBITDA | D22: =D11+D14 | E22: =E11+E14 | F22: =F11+F14 | G22: =G11+G14 | H22: =H11+H14 | I22: =I11+I14
B26: 情境假設 SCENARIO INPUTS（可編輯）
B27: 營收成長 (FY26→FY30) | E27: FY26E | F27: FY27E | G27: FY28E | H27: FY29E | I27: FY30E
B28: 熊 Bear | E28: 0.22 | F28: 0.15 | G28: 0.1 | H28: 0.07 | I28: 0.05
B29: 基 Base | E29: 0.27 | F29: 0.22 | G29: 0.16 | H29: 0.12 | I29: 0.09
B30: 牛 Bull | E30: 0.32 | F30: 0.28 | G30: 0.22 | H30: 0.17 | I30: 0.12
B31: EBIT 利潤率 (FY26→FY30) | E31: FY26E | F31: FY27E | G31: FY28E | H31: FY29E | I31: FY30E
B32: 熊 Bear | E32: 0.195 | F32: 0.2 | G32: 0.205 | H32: 0.21 | I32: 0.21
B33: 基 Base | E33: 0.2 | F33: 0.21 | G33: 0.22 | H33: 0.225 | I33: 0.23
B34: 牛 Bull | E34: 0.205 | F34: 0.22 | G34: 0.235 | H34: 0.245 | I34: 0.25
B36: 估值橋接 VALUATION BRIDGE
B37: 顯性期 PV 合計 (FCFF) | D37: =SUM(E20:I20) | E37: FY26–FY30 折現後現金流加總
B38: 終年 EBITDA (FY30E) | D38: =I22
B39: 終值 TV (Exit Multiple 法) | D39: =I22*$L$5 | E39: =終年 EBITDA × 終值 EV/EBITDA 倍數
B40: 終值現值 PV of TV | D40: =D39*I19
B41: 企業價值 EV | D41: =D37+D40
B42: 減：淨負債 Net Debt | D42: =$L$10
B43: 股權價值 Equity Value | D43: =D41-D42
B44: 股數 (bn) | D44: =$L$11
B45: 每股價值 (Exit Mult.) | D45: =D43/D44
...

Sheet Sensitivity
B1: 敏感度分析 SENSITIVITY（基於目前情境之 FCFF 流）
B3: 每股價值：WACC × 終值 EV/EBITDA
B5: WACC ↓ / 倍數 → | C5: 16 | D5: 18 | E5: 20 | F5: 22 | G5: 24 | H5: 26
B6: 0.085 | C6: =(SUMPRODUCT(DCF!$E$17:$I$17,1/(1+0.085)^DCF!$E$18:$I$18)+(DCF!$I$22*16)/(1+0.085)^DCF!$I$18-DCF!$L$10)/DCF!$L$11 | D6: =(SUMPRODUCT(DCF!$E$17:$I$17,1/(1+0.085)^DCF!$E$18:$I$18)+(DCF!$I$22*18)/(1+0.085)^DCF!$I$18-DCF!$L$10)/DCF!$L$11 | E6: =(SUMPRODUCT(DCF!$E$17:$I$17,1/(1+0.085)^DCF!$E$18:$I$18)+(DCF!$I$22*20)/(1+0.085)^DCF!$I$18-DCF!$L$10)/DCF!$L$11 | F6: =(SUMPRODUCT(DCF!$E$17:$I$17,1/(1+0.085)^DCF!$E$18:$I$18)+(DCF!$I$22*22)/(1+0.085)^DCF!$I$18-DCF!$L$10)/DCF!$L$11 | G6: =(SUMPRODUCT(DCF!$E$17:$I$17,1/(1+0.085)^DCF!$E$18:$I$18)+(DCF!$I$22*24)/(1+0.085)^DCF!$I$18-DCF!$L$10)/DCF!$L$11 | H6: =(SUMPRODUCT(DCF!$E$17:$I$17,1/(1+0.085)^DCF!$E$18:$I$18)+(DCF!$I$22*26)/(1+0.085)^DCF!$I$18-DCF!$L$10)/DCF!$L$11
B7: 0.09 | C7: =(SUMPRODUCT(DCF!$E$17:$I$17,1/(1+0.09)^DCF!$E$18:$I$18)+(DCF!$I$22*16)/(1+0.09)^DCF!$I$18-DCF!$L$10)/DCF!$L$11 | D7: =(SUMPRODUCT(DCF!$E$17:$I$17,1/(1+0.09)^DCF!$E$18:$I$18)+(DCF!$I$22*18)/(1+0.09)^DCF!$I$18-DCF!$L$10)/DCF!$L$11 | E7: =(SUMPRODUCT(DCF!$E$17:$I$17,1/(1+0.09)^DCF!$E$18:$I$18)+(DCF!$I$22*20)/(1+0.09)^DCF!$I$18-DCF!$L$10)/DCF!$L$11 | F7: =(SUMPRODUCT(DCF!$E$17:$I$17,1/(1+0.09)^DCF!$E$18:$I$18)+(DCF!$I$22*22)/(1+0.09)^DCF!$I$18-DCF!$L$10)/DCF!$L$11 | G7: =(SUMPRODUCT(DCF!$E$17:$I$17,1/(1+0.09)^DCF!$E$18:$I$18)+(DCF!$I$22*24)/(1+0.09)^DCF!$I$18-DCF!$L$10)/DCF!$L$11 | H7: =(SUMPRODUCT(DCF!$E$17:$I$17,1/(1+0.09)^DCF!$E$18:$I$18)+(DCF!$I$22*26)/(1+0.09)^DCF!$I$18-DCF!$L$10)/DCF!$L$11
B8: 0.095 | C8: =(SUMPRODUCT(DCF!$E$17:$I$17,1/(1+0.095)^DCF!$E$18:$I$18)+(DCF!$I$22*16)/(1+0.095)^DCF!$I$18-DCF!$L$10)/DCF!$L$11 | D8: =(SUMPRODUCT(DCF!$E$17:$I$17,1/(1+0.095)^DCF!$E$18:$I$18)+(DCF!$I$22*18)/(1+0.095)^DCF!$I$18-DCF!$L$10)/DCF!$L$11 | E8: =(SUMPRODUCT(DCF!$E$17:$I$17,1/(1+0.095)^DCF!$E$18:$I$18)+(DCF!$I$22*20)/(1+0.095)^DCF!$I$18-DCF!$L$10)/DCF!$L$11 | F8: =(SUMPRODUCT(DCF!$E$17:$I$17,1/(1+0.095)^DCF!$E$18:$I$18)+(DCF!$I$22*22)/(1+0.095)^DCF!$I$18-DCF!$L$10)/DCF!$L$11 | G8: =(SUMPRODUCT(DCF!$E$17:$I$17,1/(1+0.095)^DCF!$E$18:$I$18)+(DCF!$I$22*24)/(1+0.095)^DCF!$I$18-DCF!$L$10)/DCF!$L$11 | H8: =(SUMPRODUCT(DCF!$E$17:$I$17,1/(1+0.095)^DCF!$E$18:$I$18)+(DCF!$I$22*26)/(1+0.095)^DCF!$I$18-DCF!$L$10)/DCF!$L$11
B9: 0.1 | C9: =(SUMPRODUCT(DCF!$E$17:$I$17,1/(1+0.1)^DCF!$E$18:$I$18)+(DCF!$I$22*16)/(1+0.1)^DCF!$I$18-DCF!$L$10)/DCF!$L$11 | D9: =(SUMPRODUCT(DCF!$E$17:$I$17,1/(1+0.1)^DCF!$E$18:$I$18)+(DCF!$I$22*18)/(1+0.1)^DCF!$I$18-DCF!$L$10)/DCF!$L$11 | E9: =(SUMPRODUCT(DCF!$E$17:$I$17,1/(1+0.1)^DCF!$E$18:$I$18)+(DCF!$I$22*20)/(1+0.1)^DCF!$I$18-DCF!$L$10)/DCF!$L$11 | F9: =(SUMPRODUCT(DCF!$E$17:$I$17,1/(1+0.1)^DCF!$E$18:$I$18)+(DCF!$I$22*22)/(1+0.1)^DCF!$I$18-DCF!$L$10)/DCF!$L$11 | G9: =(SUMPRODUCT(DCF!$E$17:$I$17,1/(1+0.1)^DCF!$E$18:$I$18)+(DCF!$I$22*24)/(1+0.1)^DCF!$I$18-DCF!$L$10)/DCF!$L$11 | H9: =(SUMPRODUCT(DCF!$E$17:$I$17,1/(1+0.1)^DCF!$E$18:$I$18)+(DCF!$I$22*26)/(1+0.1)^DCF!$I$18-DCF!$L$10)/DCF!$L$11
B10: 0.105 | C10: =(SUMPRODUCT(DCF!$E$17:$I$17,1/(1+0.105)^DCF!$E$18:$I$18)+(DCF!$I$22*16)/(1+0.105)^DCF!$I$18-DCF!$L$10)/DCF!$L$11 | D10: =(SUMPRODUCT(DCF!$E$17:$I$17,1/(1+0.105)^DCF!$E$18:$I$18)+(DCF!$I$22*18)/(1+0.105)^DCF!$I$18-DCF!$L$10)/DCF!$L$11 | E10: =(SUMPRODUCT(DCF!$E$17:$I$17,1/(1+0.105)^DCF!$E$18:$I$18)+(DCF!$I$22*20)/(1+0.105)^DCF!$I$18-DCF!$L$10)/DCF!$L$11 | F10: =(SUMPRODUCT(DCF!$E$17:$I$17,1/(1+0.105)^DCF!$E$18:$I$18)+(DCF!$I$22*22)/(1+0.105)^DCF!$I$18-DCF!$L$10)/DCF!$L$11 | G10: =(SUMPRODUCT(DCF!$E$17:$I$17,1/(1+0.105)^DCF!$E$18:$I$18)+(DCF!$I$22*24)/(1+0.105)^DCF!$I$18-DCF!$L$10)/DCF!$L$11 | H10: =(SUMPRODUCT(DCF!$E$17:$I$17,1/(1+0.105)^DCF!$E$18:$I$18)+(DCF!$I$22*26)/(1+0.105)^DCF!$I$18-DCF!$L$10)/DCF!$L$11
B11: 0.11 | C11: =(SUMPRODUCT(DCF!$E$17:$I$17,1/(1+0.11)^DCF!$E$18:$I$18)+(DCF!$I$22*16)/(1+0.11)^DCF!$I$18-DCF!$L$10)/DCF!$L$11 | D11: =(SUMPRODUCT(DCF!$E$17:$I$17,1/(1+0.11)^DCF!$E$18:$I$18)+(DCF!$I$22*18)/(1+0.11)^DCF!$I$18-DCF!$L$10)/DCF!$L$11 | E11: =(SUMPRODUCT(DCF!$E$17:$I$17,1/(1+0.11)^DCF!$E$18:$I$18)+(DCF!$I$22*20)/(1+0.11)^DCF!$I$18-DCF!$L$10)/DCF!$L$11 | F11: =(SUMPRODUCT(DCF!$E$17:$I$17,1/(1+0.11)^DCF!$E$18:$I$18)+(DCF!$I$22*22)/(1+0.11)^DCF!$I$18-DCF!$L$10)/DCF!$L$11 | G11: =(SUMPRODUCT(DCF!$E$17:$I$17,1/(1+0.11)^DCF!$E$18:$I$18)+(DCF!$I$22*24)/(1+0.11)^DCF!$I$18-DCF!$L$10)/DCF!$L$11 | H11: =(SUMPRODUCT(DCF!$E$17:$I$17,1/(1+0.11)^DCF!$E$18:$I$18)+(DCF!$I$22*26)/(1+0.11)^DCF!$I$18-DCF!$L$10)/DCF!$L$11
B12: 0.115 | C12: =(SUMPRODUCT(DCF!$E$17:$I$17,1/(1+0.115)^DCF!$E$18:$I$18)+(DCF!$I$22*16)/(1+0.115)^DCF!$I$18-DCF!$L$10)/DCF!$L$11 | D12: =(SUMPRODUCT(DCF!$E$17:$I$17,1/(1+0.115)^DCF!$E$18:$I$18)+(DCF!$I$22*18)/(1+0.115)^DCF!$I$18-DCF!$L$10)/DCF!$L$11 | E12: =(SUMPRODUCT(DCF!$E$17:$I$17,1/(1+0.115)^DCF!$E$18:$I$18)+(DCF!$I$22*20)/(1+0.115)^DCF!$I$18-DCF!$L$10)/DCF!$L$11 | F12: =(SUMPRODUCT(DCF!$E$17:$I$17,1/(1+0.115)^DCF!$E$18:$I$18)+(DCF!$I$22*22)/(1+0.115)^DCF!$I$18-DCF!$L$10)/DCF!$L$11 | G12: =(SUMPRODUCT(DCF!$E$17:$I$17,1/(1+0.115)^DCF!$E$18:$I$18)+(DCF!$I$22*24)/(1+0.115)^DCF!$I$18-DCF!$L$10)/DCF!$L$11 | H12: =(SUMPRODUCT(DCF!$E$17:$I$17,1/(1+0.115)^DCF!$E$18:$I$18)+(DCF!$I$22*26)/(1+0.115)^DCF!$I$18-DCF!$L$10)/DCF!$L$11
B15: 每股價值：WACC × 終值成長 g（永續法）
B17: WACC ↓ / g → | C17: 0.025 | D17: 0.03 | E17: 0.035 | F17: 0.04 | G17: 0.045
B18: 0.085 | C18: =(SUMPRODUCT(DCF!$E$17:$I$17,1/(1+0.085)^DCF!$E$18:$I$18)+((DCF!$I$17*(1+0.025))/(0.085-0.025))/(1+0.085)^DCF!$I$18-DCF!$L$10)/DCF!$L$11 | D18: =(SUMPRODUCT(DCF!$E$17:$I$17,1/(1+0.085)^DCF!$E$18:$I$18)+((DCF!$I$17*(1+0.03))/(0.085-0.03))/(1+0.085)^DCF!$I$18-DCF!$L$10)/DCF!$L$11 | E18: =(SUMPRODUCT(DCF!$E$17:$I$17,1/(1+0.085)^DCF!$E$18:$I$18)+((DCF!$I$17*(1+0.035))/(0.085-0.035))/(1+0.085)^DCF!$I$18-DCF!$L$10)/DCF!$L$11 | F18: =(SUMPRODUCT(DCF!$E$17:$I$17,1/(1+0.085)^DCF!$E$18:$I$18)+((DCF!$I$17*(1+0.04))/(0.085-0.04))/(1+0.085)^DCF!$I$18-DCF!$L$10)/DCF!$L$11 | G18: =(SUMPRODUCT(DCF!$E$17:$I$17,1/(1+0.085)^DCF!$E$18:$I$18)+((DCF!$I$17*(1+0.045))/(0.085-0.045))/(1+0.085)^DCF!$I$18-DCF!$L$10)/DCF!$L$11
B19: 0.09 | C19: =(SUMPRODUCT(DCF!$E$17:$I$17,1/(1+0.09)^DCF!$E$18:$I$18)+((DCF!$I$17*(1+0.025))/(0.09-0.025))/(1+0.09)^DCF!$I$18-DCF!$L$10)/DCF!$L$11 | D19: =(SUMPRODUCT(DCF!$E$17:$I$17,1/(1+0.09)^DCF!$E$18:$I$18)+((DCF!$I$17*(1+0.03))/(0.09-0.03))/(1+0.09)^DCF!$I$18-DCF!$L$10)/DCF!$L$11 | E19: =(SUMPRODUCT(DCF!$E$17:$I$17,1/(1+0.09)^DCF!$E$18:$I$18)+((DCF!$I$17*(1+0.035))/(0.09-0.035))/(1+0.09)^DCF!$I$18-DCF!$L$10)/DCF!$L$11 | F19: =(SUMPRODUCT(DCF!$E$17:$I$17,1/(1+0.09)^DCF!$E$18:$I$18)+((DCF!$I$17*(1+0.04))/(0.09-0.04))/(1+0.09)^DCF!$I$18-DCF!$L$10)/DCF!$L$11 | G19: =(SUMPRODUCT(DCF!$E$17:$I$17,1/(1+0.09)^DCF!$E$18:$I$18)+((DCF!$I$17*(1+0.045))/(0.09-0.045))/(1+0.09)^DCF!$I$18-DCF!$L$10)/DCF!$L$11
B20: 0.095 | C20: =(SUMPRODUCT(DCF!$E$17:$I$17,1/(1+0.095)^DCF!$E$18:$I$18)+((DCF!$I$17*(1+0.025))/(0.095-0.025))/(1+0.095)^DCF!$I$18-DCF!$L$10)/DCF!$L$11 | D20: =(SUMPRODUCT(DCF!$E$17:$I$17,1/(1+0.095)^DCF!$E$18:$I$18)+((DCF!$I$17*(1+0.03))/(0.095-0.03))/(1+0.095)^DCF!$I$18-DCF!$L$10)/DCF!$L$11 | E20: =(SUMPRODUCT(DCF!$E$17:$I$17,1/(1+0.095)^DCF!$E$18:$I$18)+((DCF!$I$17*(1+0.035))/(0.095-0.035))/(1+0.095)^DCF!$I$18-DCF!$L$10)/DCF!$L$11 | F20: =(SUMPRODUCT(DCF!$E$17:$I$17,1/(1+0.095)^DCF!$E$18:$I$18)+((DCF!$I$17*(1+0.04))/(0.095-0.04))/(1+0.095)^DCF!$I$18-DCF!$L$10)/DCF!$L$11 | G20: =(SUMPRODUCT(DCF!$E$17:$I$17,1/(1+0.095)^DCF!$E$18:$I$18)+((DCF!$I$17*(1+0.045))/(0.095-0.045))/(1+0.095)^DCF!$I$18-DCF!$L$10)/DCF!$L$11
B21: 0.1 | C21: =(SUMPRODUCT(DCF!$E$17:$I$17,1/(1+0.1)^DCF!$E$18:$I$18)+((DCF!$I$17*(1+0.025))/(0.1-0.025))/(1+0.1)^DCF!$I$18-DCF!$L$10)/DCF!$L$11 | D21: =(SUMPRODUCT(DCF!$E$17:$I$17,1/(1+0.1)^DCF!$E$18:$I$18)+((DCF!$I$17*(1+0.03))/(0.1-0.03))/(1+0.1)^DCF!$I$18-DCF!$L$10)/DCF!$L$11 | E21: =(SUMPRODUCT(DCF!$E$17:$I$17,1/(1+0.1)^DCF!$E$18:$I$18)+((DCF!$I$17*(1+0.035))/(0.1-0.035))/(1+0.1)^DCF!$I$18-DCF!$L$10)/DCF!$L$11 | F21: =(SUMPRODUCT(DCF!$E$17:$I$17,1/(1+0.1)^DCF!$E$18:$I$18)+((DCF!$I$17*(1+0.04))/(0.1-0.04))/(1+0.1)^DCF!$I$18-DCF!$L$10)/DCF!$L$11 | G21: =(SUMPRODUCT(DCF!$E$17:$I$17,1/(1+0.1)^DCF!$E$18:$I$18)+((DCF!$I$17*(1+0.045))/(0.1-0.045))/(1+0.1)^DCF!$I$18-DCF!$L$10)/DCF!$L$11
B22: 0.105 | C22: =(SUMPRODUCT(DCF!$E$17:$I$17,1/(1+0.105)^DCF!$E$18:$I$18)+((DCF!$I$17*(1+0.025))/(0.105-0.025))/(1+0.105)^DCF!$I$18-DCF!$L$10)/DCF!$L$11 | D22: =(SUMPRODUCT(DCF!$E$17:$I$17,1/(1+0.105)^DCF!$E$18:$I$18)+((DCF!$I$17*(1+0.03))/(0.105-0.03))/(1+0.105)^DCF!$I$18-DCF!$L$10)/DCF!$L$11 | E22: =(SUMPRODUCT(DCF!$E$17:$I$17,1/(1+0.105)^DCF!$E$18:$I$18)+((DCF!$I$17*(1+0.035))/(0.105-0.035))/(1+0.105)^DCF!$I$18-DCF!$L$10)/DCF!$L$11 | F22: =(SUMPRODUCT(DCF!$E$17:$I$17,1/(1+0.105)^DCF!$E$18:$I$18)+((DCF!$I$17*(1+0.04))/(0.105-0.04))/(1+0.105)^DCF!$I$18-DCF!$L$10)/DCF!$L$11 | G22: =(SUMPRODUCT(DCF!$E$17:$I$17,1/(1+0.105)^DCF!$E$18:$I$18)+((DCF!$I$17*(1+0.045))/(0.105-0.045))/(1+0.105)^DCF!$I$18-DCF!$L$10)/DCF!$L$11
B23: 0.11 | C23: =(SUMPRODUCT(DCF!$E$17:$I$17,1/(1+0.11)^DCF!$E$18:$I$18)+((DCF!$I$17*(1+0.025))/(0.11-0.025))/(1+0.11)^DCF!$I$18-DCF!$L$10)/DCF!$L$11 | D23: =(SUMPRODUCT(DCF!$E$17:$I$17,1/(1+0.11)^DCF!$E$18:$I$18)+((DCF!$I$17*(1+0.03))/(0.11-0.03))/(1+0.11)^DCF!$I$18-DCF!$L$10)/DCF!$L$11 | E23: =(SUMPRODUCT(DCF!$E$17:$I$17,1/(1+0.11)^DCF!$E$18:$I$18)+((DCF!$I$17*(1+0.035))/(0.11-0.035))/(1+0.11)^DCF!$I$18-DCF!$L$10)/DCF!$L$11 | F23: =(SUMPRODUCT(DCF!$E$17:$I$17,1/(1+0.11)^DCF!$E$18:$I$18)+((DCF!$I$17*(1+0.04))/(0.11-0.04))/(1+0.11)^DCF!$I$18-DCF!$L$10)/DCF!$L$11 | G23: =(SUMPRODUCT(DCF!$E$17:$I$17,1/(1+0.11)^DCF!$E$18:$I$18)+((DCF!$I$17*(1+0.045))/(0.11-0.045))/(1+0.11)^DCF!$I$18-DCF!$L$10)/DCF!$L$11
B24: 0.115 | C24: =(SUMPRODUCT(DCF!$E$17:$I$17,1/(1+0.115)^DCF!$E$18:$I$18)+((DCF!$I$17*(1+0.025))/(0.115-0.025))/(1+0.115)^DCF!$I$18-DCF!$L$10)/DCF!$L$11 | D24: =(SUMPRODUCT(DCF!$E$17:$I$17,1/(1+0.115)^DCF!$E$18:$I$18)+((DCF!$I$17*(1+0.03))/(0.115-0.03))/(1+0.115)^DCF!$I$18-DCF!$L$10)/DCF!$L$11 | E24: =(SUMPRODUCT(DCF!$E$17:$I$17,1/(1+0.115)^DCF!$E$18:$I$18)+((DCF!$I$17*(1+0.035))/(0.115-0.035))/(1+0.115)^DCF!$I$18-DCF!$L$10)/DCF!$L$11 | F24: =(SUMPRODUCT(DCF!$E$17:$I$17,1/(1+0.115)^DCF!$E$18:$I$18)+((DCF!$I$17*(1+0.04))/(0.115-0.04))/(1+0.115)^DCF!$I$18-DCF!$L$10)/DCF!$L$11 | G24: =(SUMPRODUCT(DCF!$E$17:$I$17,1/(1+0.115)^DCF!$E$18:$I$18)+((DCF!$I$17*(1+0.045))/(0.115-0.045))/(1+0.115)^DCF!$I$18-DCF!$L$10)/DCF!$L$11
B26: 註：敏感度表使用 DCF 分頁『目前情境』之 FCFF 與終年 EBITDA。切換情境(DCF!L2)後此表同步更新。

Sheet Summary
B1: Vertiv (VRT) — DCF 估值總結
B2: 目前情境見 DCF!L2（1熊/2基/3牛，預設 2 基準）· 切換後本頁同步更新
B4: 每股價值（終值倍數法） | D4: =DCF!D45
B5: 每股價值（永續成長法） | D5: =DCF!D53
B6: 現價 | D6: =DCF!L12
B7: 上漲/下跌空間 | D7: =DCF!D45/DCF!L12-1
B8: 企業價值 EV ($bn) | D8: =DCF!D41
B9: 股權價值 ($bn) | D9: =DCF!D43
B10: DCF 隱含 EV/EBITDA (FY26E) | D10: =DCF!D54
B11: 終值占 EV 比重 | D11: =DCF!D55
B12: WACC | D12: =DCF!L3
B13: 終值成長 g | D13: =DCF!L4
B14: 終值 EV/EBITDA | D14: =DCF!L5
B16: Comps 交叉驗證（同業，資料約 2026/6）
B17: 同業 EV/EBITDA 中位（散熱相關） | D17: ~23x
B18: Vertiv 現行 EV/EBITDA | D18: ~51x
B19: 同業 Fwd P/E 中位 | D19: ~28x
B20: 解讀 | D20: DCF 隱含倍數應落在『同業中位 ~ Vertiv 溢價』之間；高於 51x 須檢視成長假設是否過樂觀
B23: 關鍵假設與風險
B24: • 營收：FY26 +27%（指引中點 ~$13.75B）→ FY30 +9%；液冷segment 約 40% CAGR 為主要上行來源。
B25: • 利潤率：EBIT 由 ~19% 擴張至 ~23%（營運槓桿 + 高階液冷組合）。
B26: • 終值倍數 22x 為『正常化』後估計（Vertiv 現 ~51x 不可持續）；保守採同業偏高水準。
B27: • 風險：① 雲端資本支出 2027–28 消化 ② 整併/價格競爭 ③ 電網瓶頸拖累建置 ④ 高估值對成長落空敏感。
B28: • 代碼校正提醒：本檔為 VRT；台股同業 Auras=3324、AVC=3017。
